Workbook

Sheet Read me
A1: Gas-mixture study: mixtures for an Ar-rich (>= 90 %) TPC at up to 10 bar
A3: Purpose | B3: Magboltz transport and Townsend properties for every candidate mixture at 1-10 bar, to choose the 4-6 mixtures for the single-GEM simulations. Plan: PLAN.md.
A4: Constraints | B4: Ar >= 90 % by volume; only nuclei lighter than Ar; drift (diffusion, velocity, attachment, electron lifetime) acceptable for a long-drift TPC; gain reachable with GEMs at 10 bar.
A5: Mixtures | B5: One row per mixture. Volume fractions in %, Ar = 100 - the rest. Priority sets the pressures run (Run grid). Grey columns are formulas.
A6: Components | B6: Properties used by the formulas (molar mass, ionisation energy, LEL), with sources.
A7: Criteria | B7: Detector requirements (drift length, drift field, gain) and the per-foil gain targets derived from them.
A8: Run grid | B8: Pressures, field grids, Penning r grid and the compute budget. Blue cells are inputs.
A9: Impurities | B9: Electron-lifetime runs: O2 / H2O admixtures to selected base mixtures (drift fields only).
A10: Outputs | B10: What is extracted per mixture and pressure, and the figure of merit it feeds.
A11: Validation | B11: Measured data to check Magboltz + Garfield against before trusting the sweep.
A12: Legend | B12: Blue text: input, edit freely. Black: formula. Yellow fill: key assumption to revisit. Priority fill: green A (first, all pressures), yellow B (1, 4, 10 bar), grey C (1, 10 bar).
A13: Regenerate | B13: python studies/gas_mixture_study/build_mixtures.py (also writes mixtures.csv for the driver).

Sheet Mixtures
A1: ID | B1: Family | C1: Priority | D1: Mixture (vol %) | E1: Comp 2 | F1: x2 (%) | G1: Comp 3 | H1: x3 (%) | I1: Comp 4 | J1: x4 (%) | K1: Ar (vol %) | L1: Mean molar mass (g/mol) | M1: Ar mass fraction | N1: Lowest IP (eV) | O1: Ar levels eligible for Penning | P1: Flammable content (vol %) | Q1: Non-Ar nuclei | R1: Penning r in Garfield | S1: Pressures run | T1: CPU h (tables) | U1: Rationale | V1: Risks / remarks | W1: Validation data
A2: R01 | B2: Reference | C2: C | D2: Ar 100 | K2: =100-F2-H2-J2 | L2: =(K2*INDEX(Components!$D$2:$D$17,MATCH("ar",Components!$A$2:$A$17,0))+IF(E2="",0,F2*INDEX(Components!$D$2:$D$17,MATCH(E2,Components!$A$2:$A$17,0)))+IF(G2="",0,H2*INDEX(Components!$D$2:$D$17,MATCH(G2,Components!$A$2:$A$17,0)))+IF(I2="",0,J2*INDEX(Components!$D$2:$D$17,MATCH(I2,Components!$A$2:$A$17,0))))/100 | M2: =K2*INDEX(Components!$D$2:$D$17,MATCH("ar",Components!$A$2:$A$17,0))/(K2*INDEX(Components!$D$2:$D$17,MATCH("ar",Components!$A$2:$A$17,0))+IF(E2="",0,F2*INDEX(Components!$D$2:$D$17,MATCH(E2,Components!$A$2:$A$17,0)))+IF(G2="",0,H2*INDEX(Components!$D$2:$D$17,MATCH(G2,Components!$A$2:$A$17,0)))+IF(I2="",0,J2*INDEX(Components!$D$2:$D$17,MATCH(I2,Components!$A$2:$A$17,0)))) | N2: =MIN(15.76,IF(E2="",99,INDEX(Components!$E$2:$E$17,MATCH(E2,Components!$A$2:$A$17,0))),IF(G2="",99,INDEX(Components!$E$2:$E$17,MATCH(G2,Components!$A$2:$A$17,0))),IF(I2="",99,INDEX(Components!$E$2:$E$17,MATCH(I2,Components!$A$2:$A$17,0)))) | O2: =IF(N2<11.55,"4s, 4p and higher",IF(N2<12.91,"4p and higher",IF(N2<13.85,"3d/5s and higher",IF(N2<15.76,"high Rydberg only","none")))) | P2: =IF(E2="",0,IF(INDEX(Components!$F$2:$F$17,MATCH(E2,Components!$A$2:$A$17,0))>0,F2,0))+IF(G2="",0,IF(INDEX(Components!$F$2:$F$17,MATCH(G2,Components!$A$2:$A$17,0))>0,H2,0))+IF(I2="",0,IF(INDEX(Components!$F$2:$F$17,MATCH(I2,Components!$A$2:$A$17,0))>0,J2,0)) | Q2: - | R2: n/a | S2: =IF(C2="A",'Run grid'!$B$4,IF(C2="B",'Run grid'!$B$6,'Run grid'!$B$8)) | T2: =S2*'Run grid'!$B$22 | U2: Pure Ar: baseline for every alpha and drift comparison | V2: Not operable (no quencher) | W2: Magboltz validation data
A3: R02 | B3: Reference | C3: C | D3: Ar:Ne 90:10 | E3: ne | F3: 10 | K3: =100-F3-H3-J3 | L3: =(K3*INDEX(Components!$D$2:$D$17,MATCH("ar",Components!$A$2:$A$17,0))+IF(E3="",0,F3*INDEX(Components!$D$2:$D$17,MATCH(E3,Components!$A$2:$A$17,0)))+IF(G3="",0,H3*INDEX(Components!$D$2:$D$17,MATCH(G3,Components!$A$2:$A$17,0)))+IF(I3="",0,J3*INDEX(Components!$D$2:$D$17,MATCH(I3,Components!$A$2:$A$17,0))))/100 | M3: =K3*INDEX(Components!$D$2:$D$17,MATCH("ar",Components!$A$2:$A$17,0))/(K3*INDEX(Components!$D$2:$D$17,MATCH("ar",Components!$A$2:$A$17,0))+IF(E3="",0,F3*INDEX(Components!$D$2:$D$17,MATCH(E3,Components!$A$2:$A$17,0)))+IF(G3="",0,H3*INDEX(Components!$D$2:$D$17,MATCH(G3,Components!$A$2:$A$17,0)))+IF(I3="",0,J3*INDEX(Components!$D$2:$D$17,MATCH(I3,Components!$A$2:$A$17,0)))) | N3: =MIN(15.76,IF(E3="",99,INDEX(Components!$E$2:$E$17,MATCH(E3,Components!$A$2:$A$17,0))),IF(G3="",99,INDEX(Components!$E$2:$E$17,MATCH(G3,Components!$A$2:$A$17,0))),IF(I3="",99,INDEX(Components!$E$2:$E$17,MATCH(I3,Components!$A$2:$A$17,0)))) | O3: =IF(N3<11.55,"4s, 4p and higher",IF(N3<12.91,"4p and higher",IF(N3<13.85,"3d/5s and higher",IF(N3<15.76,"high Rydberg only","none")))) | P3: =IF(E3="",0,IF(INDEX(Components!$F$2:$F$17,MATCH(E3,Components!$A$2:$A$17,0))>0,F3,0))+IF(G3="",0,IF(INDEX(Components!$F$2:$F$17,MATCH(G3,Components!$A$2:$A$17,0))>0,H3,0))+IF(I3="",0,IF(INDEX(Components!$F$2:$F$17,MATCH(I3,Components!$A$2:$A$17,0))>0,J3,0)) | Q3: Ne | R3: none: bracket r | S3: =IF(C3="A",'Run grid'!$B$4,IF(C3="B",'Run grid'!$B$6,'Run grid'!$B$8)) | T3: =S3*'Run grid'!$B$22 | U3: Ne effect on alpha with no quencher | V3: Not operable
A4: R03 | B4: Reference | C4: C | D4: Ar:He 90:10 | E4: he | F4: 10 | K4: =100-F4-H4-J4 | L4: =(K4*INDEX(Components!$D$2:$D$17,MATCH("ar",Components!$A$2:$A$17,0))+IF(E4="",0,F4*INDEX(Components!$D$2:$D$17,MATCH(E4,Components!$A$2:$A$17,0)))+IF(G4="",0,H4*INDEX(Components!$D$2:$D$17,MATCH(G4,Components!$A$2:$A$17,0)))+IF(I4="",0,J4*INDEX(Components!$D$2:$D$17,MATCH(I4,Components!$A$2:$A$17,0))))/100 | M4: =K4*INDEX(Components!$D$2:$D$17,MATCH("ar",Components!$A$2:$A$17,0))/(K4*INDEX(Components!$D$2:$D$17,MATCH("ar",Components!$A$2:$A$17,0))+IF(E4="",0,F4*INDEX(Components!$D$2:$D$17,MATCH(E4,Components!$A$2:$A$17,0)))+IF(G4="",0,H4*INDEX(Components!$D$2:$D$17,MATCH(G4,Components!$A$2:$A$17,0)))+IF(I4="",0,J4*INDEX(Components!$D$2:$D$17,MATCH(I4,Components!$A$2:$A$17,0)))) | N4: =MIN(15.76,IF(E4="",99,INDEX(Components!$E$2:$E$17,MATCH(E4,Components!$A$2:$A$17,0))),IF(G4="",99,INDEX(Components!$E$2:$E$17,MATCH(G4,Components!$A$2:$A$17,0))),IF(I4="",99,INDEX(Components!$E$2:$E$17,MATCH(I4,Components!$A$2:$A$17,0)))) | O4: =IF(N4<11.55,"4s, 4p and higher",IF(N4<12.91,"4p and higher",IF(N4<13.85,"3d/5s and higher",IF(N4<15.76,"high Rydberg only","none")))) | P4: =IF(E4="",0,IF(INDEX(Components!$F$2:$F$17,MATCH(E4,Components!$A$2:$A$17,0))>0,F4,0))+IF(G4="",0,IF(INDEX(Components!$F$2:$F$17,MATCH(G4,Components!$A$2:$A$17,0))>0,H4,0))+IF(I4="",0,IF(INDEX(Components!$F$2:$F$17,MATCH(I4,Components!$A$2:$A$17,0))>0,J4,0)) | Q4: He | R4: none: bracket r | S4: =IF(C4="A",'Run grid'!$B$4,IF(C4="B",'Run grid'!$B$6,'Run grid'!$B$8)) | T4: =S4*'Run grid'!$B$22 | U4: He effect on alpha with no quencher | V4: Not operable
A5: B01 | B5: Ar:CH4 | C5: A | D5: Ar:CH4 98:2 | E5: ch4 | F5: 2 | K5: =100-F5-H5-J5 | L5: =(K5*INDEX(Components!$D$2:$D$17,MATCH("ar",Components!$A$2:$A$17,0))+IF(E5="",0,F5*INDEX(Components!$D$2:$D$17,MATCH(E5,Components!$A$2:$A$17,0)))+IF(G5="",0,H5*INDEX(Components!$D$2:$D$17,MATCH(G5,Components!$A$2:$A$17,0)))+IF(I5="",0,J5*INDEX(Components!$D$2:$D$17,MATCH(I5,Components!$A$2:$A$17,0))))/100 | M5: =K5*INDEX(Components!$D$2:$D$17,MATCH("ar",Components!$A$2:$A$17,0))/(K5*INDEX(Components!$D$2:$D$17,MATCH("ar",Components!$A$2:$A$17,0))+IF(E5="",0,F5*INDEX(Components!$D$2:$D$17,MATCH(E5,Components!$A$2:$A$17,0)))+IF(G5="",0,H5*INDEX(Components!$D$2:$D$17,MATCH(G5,Components!$A$2:$A$17,0)))+IF(I5="",0,J5*INDEX(Components!$D$2:$D$17,MATCH(I5,Components!$A$2:$A$17,0)))) | N5: =MIN(15.76,IF(E5="",99,INDEX(Components!$E$2:$E$17,MATCH(E5,Components!$A$2:$A$17,0))),IF(G5="",99,INDEX(Components!$E$2:$E$17,MATCH(G5,Components!$A$2:$A$17,0))),IF(I5="",99,INDEX(Components!$E$2:$E$17,MATCH(I5,Components!$A$2:$A$17,0)))) | O5: =IF(N5<11.55,"4s, 4p and higher",IF(N5<12.91,"4p and higher",IF(N5<13.85,"3d/5s and higher",IF(N5<15.76,"high Rydberg only","none")))) | P5: =IF(E5="",0,IF(INDEX(Components!$F$2:$F$17,MATCH(E5,Components!$A$2:$A$17,0))>0,F5,0))+IF(G5="",0,IF(INDEX(Components!$F$2:$F$17,MATCH(G5,Components!$A$2:$A$17,0))>0,H5,0))+IF(I5="",0,IF(INDEX(Components!$F$2:$F$17,MATCH(I5,Components!$A$2:$A$17,0))>0,J5,0)) | Q5: H, C | R5: auto: p- and c-dependent (Sahin 2010) | S5: =IF(C5="A",'Run grid'!$B$4,IF(C5="B",'Run grid'!$B$6,'Run grid'!$B$8)) | T5: =S5*'Run grid'!$B$22 | U5: Lowest-quencher candidate; SimGEM's original 8 bar mixture | V5: Photon feedback at high gain | W5: Ye et al. 98:2 counter, 1-28 atm
A6: B02 | B6: Ar:CH4 | C6: B | D6: Ar:CH4 97:3 | E6: ch4 | F6: 3 | K6: =100-F6-H6-J6 | L6: =(K6*INDEX(Components!$D$2:$D$17,MATCH("ar",Components!$A$2:$A$17,0))+IF(E6="",0,F6*INDEX(Components!$D$2:$D$17,MATCH(E6,Components!$A$2:$A$17,0)))+IF(G6="",0,H6*INDEX(Components!$D$2:$D$17,MATCH(G6,Components!$A$2:$A$17,0)))+IF(I6="",0,J6*INDEX(Components!$D$2:$D$17,MATCH(I6,Components!$A$2:$A$17,0))))/100 | M6: =K6*INDEX(Components!$D$2:$D$17,MATCH("ar",Components!$A$2:$A$17,0))/(K6*INDEX(Components!$D$2:$D$17,MATCH("ar",Components!$A$2:$A$17,0))+IF(E6="",0,F6*INDEX(Components!$D$2:$D$17,MATCH(E6,Components!$A$2:$A$17,0)))+IF(G6="",0,H6*INDEX(Components!$D$2:$D$17,MATCH(G6,Components!$A$2:$A$17,0)))+IF(I6="",0,J6*INDEX(Components!$D$2:$D$17,MATCH(I6,Components!$A$2:$A$17,0)))) | N6: =MIN(15.76,IF(E6="",99,INDEX(Components!$E$2:$E$17,MATCH(E6,Components!$A$2:$A$17,0))),IF(G6="",99,INDEX(Components!$E$2:$E$17,MATCH(G6,Components!$A$2:$A$17,0))),IF(I6="",99,INDEX(Components!$E$2:$E$17,MATCH(I6,Components!$A$2:$A$17,0)))) | O6: =IF(N6<11.55,"4s, 4p and higher",IF(N6<12.91,"4p and higher",IF(N6<13.85,"3d/5s and higher",IF(N6<15.76,"high Rydberg only","none")))) | P6: =IF(E6="",0,IF(INDEX(Components!$F$2:$F$17,MATCH(E6,Components!$A$2:$A$17,0))>0,F6,0))+IF(G6="",0,IF(INDEX(Components!$F$2:$F$17,MATCH(G6,Components!$A$2:$A$17,0))>0,H6,0))+IF(I6="",0,IF(INDEX(Components!$F$2:$F$17,MATCH(I6,Components!$A$2:$A$17,0))>0,J6,0)) | Q6: H, C | R6: auto: p- and c-dependent (Sahin 2010) | S6: =IF(C6="A",'Run grid'!$B$4,IF(C6="B",'Run grid'!$B$6,'Run grid'!$B$8)) | T6: =S6*'Run grid'!$B$22 | U6: Fills the CH4 fraction scan
A7: B03 | B7: Ar:CH4 | C7: A | D7: Ar:CH4 95:5 | E7: ch4 | F7: 5 | K7: =100-F7-H7-J7 | L7: =(K7*INDEX(Components!$D$2:$D$17,MATCH("ar",Components!$A$2:$A$17,0))+IF(E7="",0,F7*INDEX(Components!$D$2:$D$17,MATCH(E7,Components!$A$2:$A$17,0)))+IF(G7="",0,H7*INDEX(Components!$D$2:$D$17,MATCH(G7,Components!$A$2:$A$17,0)))+IF(I7="",0,J7*INDEX(Components!$D$2:$D$17,MATCH(I7,Components!$A$2:$A$17,0))))/100 | M7: =K7*INDEX(Components!$D$2:$D$17,MATCH("ar",Components!$A$2:$A$17,0))/(K7*INDEX(Components!$D$2:$D$17,MATCH("ar",Components!$A$2:$A$17,0))+IF(E7="",0,F7*INDEX(Components!$D$2:$D$17,MATCH(E7,Components!$A$2:$A$17,0)))+IF(G7="",0,H7*INDEX(Components!$D$2:$D$17,MATCH(G7,Components!$A$2:$A$17,0)))+IF(I7="",0,J7*INDEX(Components!$D$2:$D$17,MATCH(I7,Components!$A$2:$A$17,0)))) | N7: =MIN(15.76,IF(E7="",99,INDEX(Components!$E$2:$E$17,MATCH(E7,Components!$A$2:$A$17,0))),IF(G7="",99,INDEX(Components!$E$2:$E$17,MATCH(G7,Components!$A$2:$A$17,0))),IF(I7="",99,INDEX(Components!$E$2:$E$17,MATCH(I7,Components!$A$2:$A$17,0)))) | O7: =IF(N7<11.55,"4s, 4p and higher",IF(N7<12.91,"4p and higher",IF(N7<13.85,"3d/5s and higher",IF(N7<15.76,"high Rydberg only","none")))) | P7: =IF(E7="",0,IF(INDEX(Components!$F$2:$F$17,MATCH(E7,Components!$A$2:$A$17,0))>0,F7,0))+IF(G7="",0,IF(INDEX(Components!$F$2:$F$17,MATCH(G7,Components!$A$2:$A$17,0))>0,H7,0))+IF(I7="",0,IF(INDEX(Components!$F$2:$F$17,MATCH(I7,Components!$A$2:$A$17,0))>0,J7,0)) | Q7: H, C | R7: auto: p- and c-dependent (Sahin 2010) | S7: =IF(C7="A",'Run grid'!$B$4,IF(C7="B",'Run grid'!$B$6,'Run grid'!$B$8)) | T7: =S7*'Run grid'!$B$22 | U7: Middle of the CH4 scan; reference for the Ne/He and donor ternaries
A8: B04 | B8: Ar:CH4 | C8: B | D8: Ar:CH4 93:7 | E8: ch4 | F8: 7 | K8: =100-F8-H8-J8 | L8: =(K8*INDEX(Components!$D$2:$D$17,MATCH("ar",Components!$A$2:$A$17,0))+IF(E8="",0,F8*INDEX(Components!$D$2:$D$17,MATCH(E8,Components!$A$2:$A$17,0)))+IF(G8="",0,H8*INDEX(Components!$D$2:$D$17,MATCH(G8,Components!$A$2:$A$17,0)))+IF(I8="",0,J8*INDEX(Components!$D$2:$D$17,MATCH(I8,Components!$A$2:$A$17,0))))/100 | M8: =K8*INDEX(Components!$D$2:$D$17,MATCH("ar",Components!$A$2:$A$17,0))/(K8*INDEX(Components!$D$2:$D$17,MATCH("ar",Components!$A$2:$A$17,0))+IF(E8="",0,F8*INDEX(Components!$D$2:$D$17,MATCH(E8,Components!$A$2:$A$17,0)))+IF(G8="",0,H8*INDEX(Components!$D$2:$D$17,MATCH(G8,Components!$A$2:$A$17,0)))+IF(I8="",0,J8*INDEX(Components!$D$2:$D$17,MATCH(I8,Components!$A$2:$A$17,0)))) | N8: =MIN(15.76,IF(E8="",99,INDEX(Components!$E$2:$E$17,MATCH(E8,Components!$A$2:$A$17,0))),IF(G8="",99,INDEX(Components!$E$2:$E$17,MATCH(G8,Components!$A$2:$A$17,0))),IF(I8="",99,INDEX(Components!$E$2:$E$17,MATCH(I8,Components!$A$2:$A$17,0)))) | O8: =IF(N8<11.55,"4s, 4p and higher",IF(N8<12.91,"4p and higher",IF(N8<13.85,"3d/5s and higher",IF(N8<15.76,"high Rydberg only","none")))) | P8: =IF(E8="",0,IF(INDEX(Components!$F$2:$F$17,MATCH(E8,Components!$A$2:$A$17,0))>0,F8,0))+IF(G8="",0,IF(INDEX(Components!$F$2:$F$17,MATCH(G8,Components!$A$2:$A$17,0))>0,H8,0))+IF(I8="",0,IF(INDEX(Components!$F$2:$F$17,MATCH(I8,Components!$A$2:$A$17,0))>0,J8,0)) | Q8: H, C | R8: auto: p- and c-dependent (Sahin 2010) | S8: =IF(C8="A",'Run grid'!$B$4,IF(C8="B",'Run grid'!$B$6,'Run grid'!$B$8)) | T8: =S8*'Run grid'!$B$22 | U8: Fills the CH4 fraction scan
A9: B05 | B9: Ar:CH4 | C9: A | D9: Ar:CH4 90:10 | E9: ch4 | F9: 10 | K9: =100-F9-H9-J9 | L9: =(K9*INDEX(Components!$D$2:$D$17,MATCH("ar",Components!$A$2:$A$17,0))+IF(E9="",0,F9*INDEX(Components!$D$2:$D$17,MATCH(E9,Components!$A$2:$A$17,0)))+IF(G9="",0,H9*INDEX(Components!$D$2:$D$17,MATCH(G9,Components!$A$2:$A$17,0)))+IF(I9="",0,J9*INDEX(Components!$D$2:$D$17,MATCH(I9,Components!$A$2:$A$17,0))))/100 | M9: =K9*INDEX(Components!$D$2:$D$17,MATCH("ar",Components!$A$2:$A$17,0))/(K9*INDEX(Components!$D$2:$D$17,MATCH("ar",Components!$A$2:$A$17,0))+IF(E9="",0,F9*INDEX(Components!$D$2:$D$17,MATCH(E9,Components!$A$2:$A$17,0)))+IF(G9="",0,H9*INDEX(Components!$D$2:$D$17,MATCH(G9,Components!$A$2:$A$17,0)))+IF(I9="",0,J9*INDEX(Components!$D$2:$D$17,MATCH(I9,Components!$A$2:$A$17,0)))) | N9: =MIN(15.76,IF(E9="",99,INDEX(Components!$E$2:$E$17,MATCH(E9,Components!$A$2:$A$17,0))),IF(G9="",99,INDEX(Components!$E$2:$E$17,MATCH(G9,Components!$A$2:$A$17,0))),IF(I9="",99,INDEX(Components!$E$2:$E$17,MATCH(I9,Components!$A$2:$A$17,0)))) | O9: =IF(N9<11.55,"4s, 4p and higher",IF(N9<12.91,"4p and higher",IF(N9<13.85,"3d/5s and higher",IF(N9<15.76,"high Rydberg only","none")))) | P9: =IF(E9="",0,IF(INDEX(Components!$F$2:$F$17,MATCH(E9,Components!$A$2:$A$17,0))>0,F9,0))+IF(G9="",0,IF(INDEX(Components!$F$2:$F$17,MATCH(G9,Components!$A$2:$A$17,0))>0,H9,0))+IF(I9="",0,IF(INDEX(Components!$F$2:$F$17,MATCH(I9,Components!$A$2:$A$17,0))>0,J9,0)) | Q9: H, C | R9: auto: p- and c-dependent (Sahin 2010) | S9: =IF(C9="A",'Run grid'!$B$4,IF(C9="B",'Run grid'!$B$6,'Run grid'!$B$8)) | T9: =S9*'Run grid'!$B$22 | U9: ND-GAr baseline (P10) | W9: Ye et al. 90:10 counter, 1-21 atm; P10 drift data
A10: B06 | B10: Ar:CO2 | C10: B | D10: Ar:CO2 98:2 | E10: co2 | F10: 2 | K10: =100-F10-H10-J10 | L10: =(K10*INDEX(Components!$D$2:$D$17,MATCH("ar",Components!$A$2:$A$17,0))+IF(E10="",0,F10*INDEX(Components!$D$2:$D$17,MATCH(E10,Components!$A$2:$A$17,0)))+IF(G10="",0,H10*INDEX(Components!$D$2:$D$17,MATCH(G10,Components!$A$2:$A$17,0)))+IF(I10="",0,J10*INDEX(Components!$D$2:$D$17,MATCH(I10,Components!$A$2:$A$17,0))))/100 | M10: =K10*INDEX(Components!$D$2:$D$17,MATCH("ar",Components!$A$2:$A$17,0))/(K10*INDEX(Components!$D$2:$D$17,MATCH("ar",Components!$A$2:$A$17,0))+IF(E10="",0,F10*INDEX(Components!$D$2:$D$17,MATCH(E10,Components!$A$2:$A$17,0)))+IF(G10="",0,H10*INDEX(Components!$D$2:$D$17,MATCH(G10,Components!$A$2:$A$17,0)))+IF(I10="",0,J10*INDEX(Components!$D$2:$D$17,MATCH(I10,Components!$A$2:$A$17,0)))) | N10: =MIN(15.76,IF(E10="",99,INDEX(Components!$E$2:$E$17,MATCH(E10,Components!$A$2:$A$17,0))),IF(G10="",99,INDEX(Components!$E$2:$E$17,MATCH(G10,Components!$A$2:$A$17,0))),IF(I10="",99,INDEX(Components!$E$2:$E$17,MATCH(I10,Components!$A$2:$A$17,0)))) | O10: =IF(N10<11.55,"4s, 4p and higher",IF(N10<12.91,"4p and higher",IF(N10<13.85,"3d/5s and higher",IF(N10<15.76,"high Rydberg only","none")))) | P10: =IF(E10="",0,IF(INDEX(Components!$F$2:$F$17,MATCH(E10,Components!$A$2:$A$17,0))>0,F10,0))+IF(G10="",0,IF(INDEX(Components!$F$2:$F$17,MATCH(G10,Components!$A$2:$A$17,0))>0,H10,0))+IF(I10="",0,IF(INDEX(Components!$F$2:$F$17,MATCH(I10,Components!$A$2:$A$17,0))>0,J10,0)) | Q10: C, O | R10: auto: 1 atm: Sahin 2014; other p: JINST 12 C01035 | S10: =IF(C10="A",'Run grid'!$B$4,IF(C10="B",'Run grid'!$B$6,'Run grid'!$B$8)) | T10: =S10*'Run grid'!$B$22 | U10: Low-diffusion family, lowest fraction | V10: Photon feedback
A11: B07 | B11: Ar:CO2 | C11: C | D11: Ar:CO2 97:3 | E11: co2 | F11: 3 | K11: =100-F11-H11-J11 | L11: =(K11*INDEX(Components!$D$2:$D$17,MATCH("ar",Components!$A$2:$A$17,0))+IF(E11="",0,F11*INDEX(Components!$D$2:$D$17,MATCH(E11,Components!$A$2:$A$17,0)))+IF(G11="",0,H11*INDEX(Components!$D$2:$D$17,MATCH(G11,Components!$A$2:$A$17,0)))+IF(I11="",0,J11*INDEX(Components!$D$2:$D$17,MATCH(I11,Components!$A$2:$A$17,0))))/100 | M11: =K11*INDEX(Components!$D$2:$D$17,MATCH("ar",Components!$A$2:$A$17,0))/(K11*INDEX(Components!$D$2:$D$17,MATCH("ar",Components!$A$2:$A$17,0))+IF(E11="",0,F11*INDEX(Components!$D$2:$D$17,MATCH(E11,Components!$A$2:$A$17,0)))+IF(G11="",0,H11*INDEX(Components!$D$2:$D$17,MATCH(G11,Components!$A$2:$A$17,0)))+IF(I11="",0,J11*INDEX(Components!$D$2:$D$17,MATCH(I11,Components!$A$2:$A$17,0)))) | N11: =MIN(15.76,IF(E11="",99,INDEX(Components!$E$2:$E$17,MATCH(E11,Components!$A$2:$A$17,0))),IF(G11="",99,INDEX(Components!$E$2:$E$17,MATCH(G11,Components!$A$2:$A$17,0))),IF(I11="",99,INDEX(Components!$E$2:$E$17,MATCH(I11,Components!$A$2:$A$17,0)))) | O11: =IF(N11<11.55,"4s, 4p and higher",IF(N11<12.91,"4p and higher",IF(N11<13.85,"3d/5s and higher",IF(N11<15.76,"high Rydberg only","none")))) | P11: =IF(E11="",0,IF(INDEX(Components!$F$2:$F$17,MATCH(E11,Components!$A$2:$A$17,0))>0,F11,0))+IF(G11="",0,IF(INDEX(Components!$F$2:$F$17,MATCH(G11,Components!$A$2:$A$17,0))>0,H11,0))+IF(I11="",0,IF(INDEX(Components!$F$2:$F$17,MATCH(I11,Components!$A$2:$A$17,0))>0,J11,0)) | Q11: C, O | R11: auto: 1 atm: Sahin 2014; other p: JINST 12 C01035 | S11: =IF(C11="A",'Run grid'!$B$4,IF(C11="B",'Run grid'!$B$6,'Run grid'!$B$8)) | T11: =S11*'Run grid'!$B$22 | U11: Fills the CO2 fraction scan
A12: B08 | B12: Ar:CO2 | C12: A | D12: Ar:CO2 95:5 | E12: co2 | F12: 5 | K12: =100-F12-H12-J12 | L12: =(K12*INDEX(Components!$D$2:$D$17,MATCH("ar",Components!$A$2:$A$17,0))+IF(E12="",0,F12*INDEX(Components!$D$2:$D$17,MATCH(E12,Components!$A$2:$A$17,0)))+IF(G12="",0,H12*INDEX(Components!$D$2:$D$17,MATCH(G12,Components!$A$2:$A$17,0)))+IF(I12="",0,J12*INDEX(Components!$D$2:$D$17,MATCH(I12,Components!$A$2:$A$17,0))))/100 | M12: =K12*INDEX(Components!$D$2:$D$17,MATCH("ar",Components!$A$2:$A$17,0))/(K12*INDEX(Components!$D$2:$D$17,MATCH("ar",Components!$A$2:$A$17,0))+IF(E12="",0,F12*INDEX(Components!$D$2:$D$17,MATCH(E12,Components!$A$2:$A$17,0)))+IF(G12="",0,H12*INDEX(Components!$D$2:$D$17,MATCH(G12,Components!$A$2:$A$17,0)))+IF(I12="",0,J12*INDEX(Components!$D$2:$D$17,MATCH(I12,Components!$A$2:$A$17,0)))) | N12: =MIN(15.76,IF(E12="",99,INDEX(Components!$E$2:$E$17,MATCH(E12,Components!$A$2:$A$17,0))),IF(G12="",99,INDEX(Components!$E$2:$E$17,MATCH(G12,Components!$A$2:$A$17,0))),IF(I12="",99,INDEX(Components!$E$2:$E$17,MATCH(I12,Components!$A$2:$A$17,0)))) | O12: =IF(N12<11.55,"4s, 4p and higher",IF(N12<12.91,"4p and higher",IF(N12<13.85,"3d/5s and higher",IF(N12<15.76,"high Rydberg only","none")))) | P12: =IF(E12="",0,IF(INDEX(Components!$F$2:$F$17,MATCH(E12,Components!$A$2:$A$17,0))>0,F12,0))+IF(G12="",0,IF(INDEX(Components!$F$2:$F$17,MATCH(G12,Components!$A$2:$A$17,0))>0,H12,0))+IF(I12="",0,IF(INDEX(Components!$F$2:$F$17,MATCH(I12,Components!$A$2:$A$17,0))>0,J12,0)) | Q12: C, O | R12: auto: 1 atm: Sahin 2014; other p: JINST 12 C01035 | S12: =IF(C12="A",'Run grid'!$B$4,IF(C12="B",'Run grid'!$B$6,'Run grid'!$B$8)) | T12: =S12*'Run grid'!$B$22 | U12: Low-diffusion candidate | V12: O2 three-body attachment
A13: B09 | B13: Ar:CO2 | C13: C | D13: Ar:CO2 93:7 | E13: co2 | F13: 7 | K13: =100-F13-H13-J13 | L13: =(K13*INDEX(Components!$D$2:$D$17,MATCH("ar",Components!$A$2:$A$17,0))+IF(E13="",0,F13*INDEX(Components!$D$2:$D$17,MATCH(E13,Components!$A$2:$A$17,0)))+IF(G13="",0,H13*INDEX(Components!$D$2:$D$17,MATCH(G13,Components!$A$2:$A$17,0)))+IF(I13="",0,J13*INDEX(Components!$D$2:$D$17,MATCH(I13,Components!$A$2:$A$17,0))))/100 | M13: =K13*INDEX(Components!$D$2:$D$17,MATCH("ar",Components!$A$2:$A$17,0))/(K13*INDEX(Components!$D$2:$D$17,MATCH("ar",Components!$A$2:$A$17,0))+IF(E13="",0,F13*INDEX(Components!$D$2:$D$17,MATCH(E13,Components!$A$2:$A$17,0)))+IF(G13="",0,H13*INDEX(Components!$D$2:$D$17,MATCH(G13,Components!$A$2:$A$17,0)))+IF(I13="",0,J13*INDEX(Components!$D$2:$D$17,MATCH(I13,Components!$A$2:$A$17,0)))) | N13: =MIN(15.76,IF(E13="",99,INDEX(Components!$E$2:$E$17,MATCH(E13,Components!$A$2:$A$17,0))),IF(G13="",99,INDEX(Components!$E$2:$E$17,MATCH(G13,Components!$A$2:$A$17,0))),IF(I13="",99,INDEX(Components!$E$2:$E$17,MATCH(I13,Components!$A$2:$A$17,0)))) | O13: =IF(N13<11.55,"4s, 4p and higher",IF(N13<12.91,"4p and higher",IF(N13<13.85,"3d/5s and higher",IF(N13<15.76,"high Rydberg only","none")))) | P13: =IF(E13="",0,IF(INDEX(Components!$F$2:$F$17,MATCH(E13,Components!$A$2:$A$17,0))>0,F13,0))+IF(G13="",0,IF(INDEX(Components!$F$2:$F$17,MATCH(G13,Components!$A$2:$A$17,0))>0,H13,0))+IF(I13="",0,IF(INDEX(Components!$F$2:$F$17,MATCH(I13,Components!$A$2:$A$17,0))>0,J13,0)) | Q13: C, O | R13: auto: 1 atm: Sahin 2014; other p: JINST 12 C01035 | S13: =IF(C13="A",'Run grid'!$B$4,IF(C13="B",'Run grid'!$B$6,'Run grid'!$B$8)) | T13: =S13*'Run grid'!$B$22 | U13: Fills the CO2 fraction scan
A14: B10 | B14: Ar:CO2 | C14: A | D14: Ar:CO2 90:10 | E14: co2 | F14: 10 | K14: =100-F14-H14-J14 | L14: =(K14*INDEX(Components!$D$2:$D$17,MATCH("ar",Components!$A$2:$A$17,0))+IF(E14="",0,F14*INDEX(Components!$D$2:$D$17,MATCH(E14,Components!$A$2:$A$17,0)))+IF(G14="",0,H14*INDEX(Components!$D$2:$D$17,MATCH(G14,Components!$A$2:$A$17,0)))+IF(I14="",0,J14*INDEX(Components!$D$2:$D$17,MATCH(I14,Components!$A$2:$A$17,0))))/100 | M14: =K14*INDEX(Components!$D$2:$D$17,MATCH("ar",Components!$A$2:$A$17,0))/(K14*INDEX(Components!$D$2:$D$17,MATCH("ar",Components!$A$2:$A$17,0))+IF(E14="",0,F14*INDEX(Components!$D$2:$D$17,MATCH(E14,Components!$A$2:$A$17,0)))+IF(G14="",0,H14*INDEX(Components!$D$2:$D$17,MATCH(G14,Components!$A$2:$A$17,0)))+IF(I14="",0,J14*INDEX(Components!$D$2:$D$17,MATCH(I14,Components!$A$2:$A$17,0)))) | N14: =MIN(15.76,IF(E14="",99,INDEX(Components!$E$2:$E$17,MATCH(E14,Components!$A$2:$A$17,0))),IF(G14="",99,INDEX(Components!$E$2:$E$17,MATCH(G14,Components!$A$2:$A$17,0))),IF(I14="",99,INDEX(Components!$E$2:$E$17,MATCH(I14,Components!$A$2:$A$17,0)))) | O14: =IF(N14<11.55,"4s, 4p and higher",IF(N14<12.91,"4p and higher",IF(N14<13.85,"3d/5s and higher",IF(N14<15.76,"high Rydberg only","none")))) | P14: =IF(E14="",0,IF(INDEX(Components!$F$2:$F$17,MATCH(E14,Components!$A$2:$A$17,0))>0,F14,0))+IF(G14="",0,IF(INDEX(Components!$F$2:$F$17,MATCH(G14,Components!$A$2:$A$17,0))>0,H14,0))+IF(I14="",0,IF(INDEX(Components!$F$2:$F$17,MATCH(I14,Components!$A$2:$A$17,0))>0,J14,0)) | Q14: C, O | R14: auto: 1 atm: Sahin 2014; other p: JINST 12 C01035 | S14: =IF(C14="A",'Run grid'!$B$4,IF(C14="B",'Run grid'!$B$6,'Run grid'!$B$8)) | T14: =S14*'Run grid'!$B$22 | U14: Low-diffusion candidate; GORG data at 1 bar | V14: O2 three-body attachment | W14: GORG Ar:CO2 90:10 (15 psi)
A15: B11 | B15: Ar:CF4 | C15: C | D15: Ar:CF4 98:2 | E15: cf4 | F15: 2 | K15: =100-F15-H15-J15 | L15: =(K15*INDEX(Components!$D$2:$D$17,MATCH("ar",Components!$A$2:$A$17,0))+IF(E15="",0,F15*INDEX(Components!$D$2:$D$17,MATCH(E15,Components!$A$2:$A$17,0)))+IF(G15="",0,H15*INDEX(Components!$D$2:$D$17,MATCH(G15,Components!$A$2:$A$17,0)))+IF(I15="",0,J15*INDEX(Components!$D$2:$D$17,MATCH(I15,Components!$A$2:$A$17,0))))/100 | M15: =K15*INDEX(Components!$D$2:$D$17,MATCH("ar",Components!$A$2:$A$17,0))/(K15*INDEX(Components!$D$2:$D$17,MATCH("ar",Components!$A$2:$A$17,0))+IF(E15="",0,F15*INDEX(Components!$D$2:$D$17,MATCH(E15,Components!$A$2:$A$17,0)))+IF(G15="",0,H15*INDEX(Components!$D$2:$D$17,MATCH(G15,Components!$A$2:$A$17,0)))+IF(I15="",0,J15*INDEX(Components!$D$2:$D$17,MATCH(I15,Components!$A$2:$A$17,0)))) | N15: =MIN(15.76,IF(E15="",99,INDEX(Components!$E$2:$E$17,MATCH(E15,Components!$A$2:$A$17,0))),IF(G15="",99,INDEX(Components!$E$2:$E$17,MATCH(G15,Components!$A$2:$A$17,0))),IF(I15="",99,INDEX(Components!$E$2:$E$17,MATCH(I15,Components!$A$2:$A$17,0)))) | O15: =IF(N15<11.55,"4s, 4p and higher",IF(N15<12.91,"4p and higher",IF(N15<13.85,"3d/5s and higher",IF(N15<15.76,"high Rydberg only","none")))) | P15: =IF(E15="",0,IF(INDEX(Components!$F$2:$F$17,MATCH(E15,Components!$A$2:$A$17,0))>0,F15,0))+IF(G15="",0,IF(INDEX(Components!$F$2:$F$17,MATCH(G15,Components!$A$2:$A$17,0))>0,H15,0))+IF(I15="",0,IF(INDEX(Components!$F$2:$F$17,MATCH(I15,Components!$A$2:$A$17,0))>0,J15,0)) | Q15: C, F | R15: none: bracket r | S15: =IF(C15="A",'Run grid'!$B$4,IF(C15="B",'Run grid'!$B$6,'Run grid'!$B$8)) | T15: =S15*'Run grid'!$B$22 | U15: Fast drift, low diffusion | V15: Hole-field attachment
A16: B12 | B16: Ar:CF4 | C16: B | D16: Ar:CF4 95:5 | E16: cf4 | F16: 5 | K16: =100-F16-H16-J16 | L16: =(K16*INDEX(Components!$D$2:$D$17,MATCH("ar",Components!$A$2:$A$17,0))+IF(E16="",0,F16*INDEX(Components!$D$2:$D$17,MATCH(E16,Components!$A$2:$A$17,0)))+IF(G16="",0,H16*INDEX(Components!$D$2:$D$17,MATCH(G16,Components!$A$2:$A$17,0)))+IF(I16="",0,J16*INDEX(Components!$D$2:$D$17,MATCH(I16,Components!$A$2:$A$17,0))))/100 | M16: =K16*INDEX(Components!$D$2:$D$17,MATCH("ar",Components!$A$2:$A$17,0))/(K16*INDEX(Components!$D$2:$D$17,MATCH("ar",Components!$A$2:$A$17,0))+IF(E16="",0,F16*INDEX(Components!$D$2:$D$17,MATCH(E16,Components!$A$2:$A$17,0)))+IF(G16="",0,H16*INDEX(Components!$D$2:$D$17,MATCH(G16,Components!$A$2:$A$17,0)))+IF(I16="",0,J16*INDEX(Components!$D$2:$D$17,MATCH(I16,Components!$A$2:$A$17,0)))) | N16: =MIN(15.76,IF(E16="",99,INDEX(Components!$E$2:$E$17,MATCH(E16,Components!$A$2:$A$17,0))),IF(G16="",99,INDEX(Components!$E$2:$E$17,MATCH(G16,Components!$A$2:$A$17,0))),IF(I16="",99,INDEX(Components!$E$2:$E$17,MATCH(I16,Components!$A$2:$A$17,0)))) | O16: =IF(N16<11.55,"4s, 4p and higher",IF(N16<12.91,"4p and higher",IF(N16<13.85,"3d/5s and higher",IF(N16<15.76,"high Rydberg only","none")))) | P16: =IF(E16="",0,IF(INDEX(Components!$F$2:$F$17,MATCH(E16,Components!$A$2:$A$17,0))>0,F16,0))+IF(G16="",0,IF(INDEX(Components!$F$2:$F$17,MATCH(G16,Components!$A$2:$A$17,0))>0,H16,0))+IF(I16="",0,IF(INDEX(Components!$F$2:$F$17,MATCH(I16,Components!$A$2:$A$17,0))>0,J16,0)) | Q16: C, F | R16: none: bracket r | S16: =IF(C16="A",'Run grid'!$B$4,IF(C16="B",'Run grid'!$B$6,'Run grid'!$B$8)) | T16: =S16*'Run grid'!$B$22 | U16: Fast drift, low diffusion | V16: Hole-field attachment; adds F nuclei
A17: B13 | B17: Ar:CF4 | C17: B | D17: Ar:CF4 90:10 | E17: cf4 | F17: 10 | K17: =100-F17-H17-J17 | L17: =(K17*INDEX(Components!$D$2:$D$17,MATCH("ar",Components!$A$2:$A$17,0))+IF(E17="",0,F17*INDEX(Components!$D$2:$D$17,MATCH(E17,Components!$A$2:$A$17,0)))+IF(G17="",0,H17*INDEX(Components!$D$2:$D$17,MATCH(G17,Components!$A$2:$A$17,0)))+IF(I17="",0,J17*INDEX(Components!$D$2:$D$17,MATCH(I17,Components!$A$2:$A$17,0))))/100 | M17: =K17*INDEX(Components!$D$2:$D$17,MATCH("ar",Components!$A$2:$A$17,0))/(K17*INDEX(Components!$D$2:$D$17,MATCH("ar",Components!$A$2:$A$17,0))+IF(E17="",0,F17*INDEX(Components!$D$2:$D$17,MATCH(E17,Components!$A$2:$A$17,0)))+IF(G17="",0,H17*INDEX(Components!$D$2:$D$17,MATCH(G17,Components!$A$2:$A$17,0)))+IF(I17="",0,J17*INDEX(Components!$D$2:$D$17,MATCH(I17,Components!$A$2:$A$17,0)))) | N17: =MIN(15.76,IF(E17="",99,INDEX(Components!$E$2:$E$17,MATCH(E17,Components!$A$2:$A$17,0))),IF(G17="",99,INDEX(Components!$E$2:$E$17,MATCH(G17,Components!$A$2:$A$17,0))),IF(I17="",99,INDEX(Components!$E$2:$E$17,MATCH(I17,Components!$A$2:$A$17,0)))) | O17: =IF(N17<11.55,"4s, 4p and higher",IF(N17<12.91,"4p and higher",IF(N17<13.85,"3d/5s and higher",IF(N17<15.76,"high Rydberg only","none")))) | P17: =IF(E17="",0,IF(INDEX(Components!$F$2:$F$17,MATCH(E17,Components!$A$2:$A$17,0))>0,F17,0))+IF(G17="",0,IF(INDEX(Components!$F$2:$F$17,MATCH(G17,Components!$A$2:$A$17,0))>0,H17,0))+IF(I17="",0,IF(INDEX(Components!$F$2:$F$17,MATCH(I17,Components!$A$2:$A$17,0))>0,J17,0)) | Q17: C, F | R17: none: bracket r | S17: =IF(C17="A",'Run grid'!$B$4,IF(C17="B",'Run grid'!$B$6,'Run grid'!$B$8)) | T17: =S17*'Run grid'!$B$22 | U17: Fast drift, low diffusion | V17: Hole-field attachment; adds F nuclei
A18: B14 | B18: Ar:C2H6 | C18: C | D18: Ar:C2H6 98:2 | E18: c2h6 | F18: 2 | K18: =100-F18-H18-J18 | L18: =(K18*INDEX(Components!$D$2:$D$17,MATCH("ar",Components!$A$2:$A$17,0))+IF(E18="",0,F18*INDEX(Components!$D$2:$D$17,MATCH(E18,Components!$A$2:$A$17,0)))+IF(G18="",0,H18*INDEX(Components!$D$2:$D$17,MATCH(G18,Components!$A$2:$A$17,0)))+IF(I18="",0,J18*INDEX(Components!$D$2:$D$17,MATCH(I18,Components!$A$2:$A$17,0))))/100 | M18: =K18*INDEX(Components!$D$2:$D$17,MATCH("ar",Components!$A$2:$A$17,0))/(K18*INDEX(Components!$D$2:$D$17,MATCH("ar",Components!$A$2:$A$17,0))+IF(E18="",0,F18*INDEX(Components!$D$2:$D$17,MATCH(E18,Components!$A$2:$A$17,0)))+IF(G18="",0,H18*INDEX(Components!$D$2:$D$17,MATCH(G18,Components!$A$2:$A$17,0)))+IF(I18="",0,J18*INDEX(Components!$D$2:$D$17,MATCH(I18,Components!$A$2:$A$17,0)))) | N18: =MIN(15.76,IF(E18="",99,INDEX(Components!$E$2:$E$17,MATCH(E18,Components!$A$2:$A$17,0))),IF(G18="",99,INDEX(Components!$E$2:$E$17,MATCH(G18,Components!$A$2:$A$17,0))),IF(I18="",99,INDEX(Components!$E$2:$E$17,MATCH(I18,Components!$A$2:$A$17,0)))) | O18: =IF(N18<11.55,"4s, 4p and higher",IF(N18<12.91,"4p and higher",IF(N18<13.85,"3d/5s and higher",IF(N18<15.76,"high Rydberg only","none")))) | P18: =IF(E18="",0,IF(INDEX(Components!$F$2:$F$17,MATCH(E18,Components!$A$2:$A$17,0))>0,F18,0))+IF(G18="",0,IF(INDEX(Components!$F$2:$F$17,MATCH(G18,Components!$A$2:$A$17,0))>0,H18,0))+IF(I18="",0,IF(INDEX(Components!$F$2:$F$17,MATCH(I18,Components!$A$2:$A$17,0))>0,J18,0)) | Q18: H, C | R18: auto: 0.31 (10 %, 1 atm only) | S18: =IF(C18="A",'Run grid'!$B$4,IF(C18="B",'Run grid'!$B$6,'Run grid'!$B$8)) | T18: =S18*'Run grid'!$B$22 | U18: Better UV quencher than CH4 | V18: Flammable
A19: B15 | B19: Ar:C2H6 | C19: B | D19: Ar:C2H6 95:5 | E19: c2h6 | F19: 5 | K19: =100-F19-H19-J19 | L19: =(K19*INDEX(Components!$D$2:$D$17,MATCH("ar",Components!$A$2:$A$17,0))+IF(E19="",0,F19*INDEX(Components!$D$2:$D$17,MATCH(E19,Components!$A$2:$A$17,0)))+IF(G19="",0,H19*INDEX(Components!$D$2:$D$17,MATCH(G19,Components!$A$2:$A$17,0)))+IF(I19="",0,J19*INDEX(Components!$D$2:$D$17,MATCH(I19,Components!$A$2:$A$17,0))))/100 | M19: =K19*INDEX(Components!$D$2:$D$17,MATCH("ar",Components!$A$2:$A$17,0))/(K19*INDEX(Components!$D$2:$D$17,MATCH("ar",Components!$A$2:$A$17,0))+IF(E19="",0,F19*INDEX(Components!$D$2:$D$17,MATCH(E19,Components!$A$2:$A$17,0)))+IF(G19="",0,H19*INDEX(Components!$D$2:$D$17,MATCH(G19,Components!$A$2:$A$17,0)))+IF(I19="",0,J19*INDEX(Components!$D$2:$D$17,MATCH(I19,Components!$A$2:$A$17,0)))) | N19: =MIN(15.76,IF(E19="",99,INDEX(Components!$E$2:$E$17,MATCH(E19,Components!$A$2:$A$17,0))),IF(G19="",99,INDEX(Components!$E$2:$E$17,MATCH(G19,Components!$A$2:$A$17,0))),IF(I19="",99,INDEX(Components!$E$2:$E$17,MATCH(I19,Components!$A$2:$A$17,0)))) | O19: =IF(N19<11.55,"4s, 4p and higher",IF(N19<12.91,"4p and higher",IF(N19<13.85,"3d/5s and higher",IF(N19<15.76,"high Rydberg only","none")))) | P19: =IF(E19="",0,IF(INDEX(Components!$F$2:$F$17,MATCH(E19,Components!$A$2:$A$17,0))>0,F19,0))+IF(G19="",0,IF(INDEX(Components!$F$2:$F$17,MATCH(G19,Components!$A$2:$A$17,0))>0,H19,0))+IF(I19="",0,IF(INDEX(Components!$F$2:$F$17,MATCH(I19,Components!$A$2:$A$17,0))>0,J19,0)) | Q19: H, C | R19: auto: 0.31 (10 %, 1 atm only) | S19: =IF(C19="A",'Run grid'!$B$4,IF(C19="B",'Run grid'!$B$6,'Run grid'!$B$8)) | T19: =S19*'Run grid'!$B$22 | U19: Better UV quencher than CH4; Penning from Ar 4s marginal | V19: Flammable
A20: B16 | B20: Ar:C2H6 | C20: C | D20: Ar:C2H6 90:10 | E20: c2h6 | F20: 10 | K20: =100-F20-H20-J20 | L20: =(K20*INDEX(Components!$D$2:$D$17,MATCH("ar",Components!$A$2:$A$17,0))+IF(E20="",0,F20*INDEX(Components!$D$2:$D$17,MATCH(E20,Components!$A$2:$A$17,0)))+IF(G20="",0,H20*INDEX(Components!$D$2:$D$17,MATCH(G20,Components!$A$2:$A$17,0)))+IF(I20="",0,J20*INDEX(Components!$D$2:$D$17,MATCH(I20,Components!$A$2:$A$17,0))))/100 | M20: =K20*INDEX(Components!$D$2:$D$17,MATCH("ar",Components!$A$2:$A$17,0))/(K20*INDEX(Components!$D$2:$D$17,MATCH("ar",Components!$A$2:$A$17,0))+IF(E20="",0,F20*INDEX(Components!$D$2:$D$17,MATCH(E20,Components!$A$2:$A$17,0)))+IF(G20="",0,H20*INDEX(Components!$D$2:$D$17,MATCH(G20,Components!$A$2:$A$17,0)))+IF(I20="",0,J20*INDEX(Components!$D$2:$D$17,MATCH(I20,Components!$A$2:$A$17,0)))) | N20: =MIN(15.76,IF(E20="",99,INDEX(Components!$E$2:$E$17,MATCH(E20,Components!$A$2:$A$17,0))),IF(G20="",99,INDEX(Components!$E$2:$E$17,MATCH(G20,Components!$A$2:$A$17,0))),IF(I20="",99,INDEX(Components!$E$2:$E$17,MATCH(I20,Components!$A$2:$A$17,0)))) | O20: =IF(N20<11.55,"4s, 4p and higher",IF(N20<12.91,"4p and higher",IF(N20<13.85,"3d/5s and higher",IF(N20<15.76,"high Rydberg only","none")))) | P20: =IF(E20="",0,IF(INDEX(Components!$F$2:$F$17,MATCH(E20,Components!$A$2:$A$17,0))>0,F20,0))+IF(G20="",0,IF(INDEX(Components!$F$2:$F$17,MATCH(G20,Components!$A$2:$A$17,0))>0,H20,0))+IF(I20="",0,IF(INDEX(Components!$F$2:$F$17,MATCH(I20,Components!$A$2:$A$17,0))>0,J20,0)) | Q20: H, C | R20: auto: 0.31 (10 %, 1 atm only) | S20: =IF(C20="A",'Run grid'!$B$4,IF(C20="B",'Run grid'!$B$6,'Run grid'!$B$8)) | T20: =S20*'Run grid'!$B$22 | U20: Only point with a published r (0.31, 1 atm) | V20: Flammable | W20: Sahin 2010 (r at 1 atm)
A21: B17 | B21: Ar:C3H8 | C21: C | D21: Ar:C3H8 98:2 | E21: c3h8 | F21: 2 | K21: =100-F21-H21-J21 | L21: =(K21*INDEX(Components!$D$2:$D$17,MATCH("ar",Components!$A$2:$A$17,0))+IF(E21="",0,F21*INDEX(Components!$D$2:$D$17,MATCH(E21,Components!$A$2:$A$17,0)))+IF(G21="",0,H21*INDEX(Components!$D$2:$D$17,MATCH(G21,Components!$A$2:$A$17,0)))+IF(I21="",0,J21*INDEX(Components!$D$2:$D$17,MATCH(I21,Components!$A$2:$A$17,0))))/100 | M21: =K21*INDEX(Components!$D$2:$D$17,MATCH("ar",Components!$A$2:$A$17,0))/(K21*INDEX(Components!$D$2:$D$17,MATCH("ar",Components!$A$2:$A$17,0))+IF(E21="",0,F21*INDEX(Components!$D$2:$D$17,MATCH(E21,Components!$A$2:$A$17,0)))+IF(G21="",0,H21*INDEX(Components!$D$2:$D$17,MATCH(G21,Components!$A$2:$A$17,0)))+IF(I21="",0,J21*INDEX(Components!$D$2:$D$17,MATCH(I21,Components!$A$2:$A$17,0)))) | N21: =MIN(15.76,IF(E21="",99,INDEX(Components!$E$2:$E$17,MATCH(E21,Components!$A$2:$A$17,0))),IF(G21="",99,INDEX(Components!$E$2:$E$17,MATCH(G21,Components!$A$2:$A$17,0))),IF(I21="",99,INDEX(Components!$E$2:$E$17,MATCH(I21,Components!$A$2:$A$17,0)))) | O21: =IF(N21<11.55,"4s, 4p and higher",IF(N21<12.91,"4p and higher",IF(N21<13.85,"3d/5s and higher",IF(N21<15.76,"high Rydberg only","none")))) | P21: =IF(E21="",0,IF(INDEX(Components!$F$2:$F$17,MATCH(E21,Components!$A$2:$A$17,0))>0,F21,0))+IF(G21="",0,IF(INDEX(Components!$F$2:$F$17,MATCH(G21,Components!$A$2:$A$17,0))>0,H21,0))+IF(I21="",0,IF(INDEX(Components!$F$2:$F$17,MATCH(I21,Components!$A$2:$A$17,0))>0,J21,0)) | Q21: H, C | R21: auto: c-dependent (1 atm only) | S21: =IF(C21="A",'Run grid'!$B$4,IF(C21="B",'Run grid'!$B$6,'Run grid'!$B$8)) | T21: =S21*'Run grid'!$B$22 | U21: Penning donor (IP 10.9 eV) | V21: Flammable | W21: Sahin 2010 (r at 1 atm)
A22: B18 | B22: Ar:C3H8 | C22: C | D22: Ar:C3H8 95:5 | E22: c3h8 | F22: 5 | K22: =100-F22-H22-J22 | L22: =(K22*INDEX(Components!$D$2:$D$17,MATCH("ar",Components!$A$2:$A$17,0))+IF(E22="",0,F22*INDEX(Components!$D$2:$D$17,MATCH(E22,Components!$A$2:$A$17,0)))+IF(G22="",0,H22*INDEX(Components!$D$2:$D$17,MATCH(G22,Components!$A$2:$A$17,0)))+IF(I22="",0,J22*INDEX(Components!$D$2:$D$17,MATCH(I22,Components!$A$2:$A$17,0))))/100 | M22: =K22*INDEX(Components!$D$2:$D$17,MATCH("ar",Components!$A$2:$A$17,0))/(K22*INDEX(Components!$D$2:$D$17,MATCH("ar",Components!$A$2:$A$17,0))+IF(E22="",0,F22*INDEX(Components!$D$2:$D$17,MATCH(E22,Components!$A$2:$A$17,0)))+IF(G22="",0,H22*INDEX(Components!$D$2:$D$17,MATCH(G22,Components!$A$2:$A$17,0)))+IF(I22="",0,J22*INDEX(Components!$D$2:$D$17,MATCH(I22,Components!$A$2:$A$17,0)))) | N22: =MIN(15.76,IF(E22="",99,INDEX(Components!$E$2:$E$17,MATCH(E22,Components!$A$2:$A$17,0))),IF(G22="",99,INDEX(Components!$E$2:$E$17,MATCH(G22,Components!$A$2:$A$17,0))),IF(I22="",99,INDEX(Components!$E$2:$E$17,MATCH(I22,Components!$A$2:$A$17,0)))) | O22: =IF(N22<11.55,"4s, 4p and higher",IF(N22<12.91,"4p and higher",IF(N22<13.85,"3d/5s and higher",IF(N22<15.76,"high Rydberg only","none")))) | P22: =IF(E22="",0,IF(INDEX(Components!$F$2:$F$17,MATCH(E22,Components!$A$2:$A$17,0))>0,F22,0))+IF(G22="",0,IF(INDEX(Components!$F$2:$F$17,MATCH(G22,Components!$A$2:$A$17,0))>0,H22,0))+IF(I22="",0,IF(INDEX(Components!$F$2:$F$17,MATCH(I22,Components!$A$2:$A$17,0))>0,J22,0)) | Q22: H, C | R22: auto: c-dependent (1 atm only) | S22: =IF(C22="A",'Run grid'!$B$4,IF(C22="B",'Run grid'!$B$6,'Run grid'!$B$8)) | T22: =S22*'Run grid'!$B$22 | U22: Penning donor (IP 10.9 eV) | V22: Flammable
A23: B19 | B23: Ar:iC4H10 | C23: B | D23: Ar:iC4H10 99:1 | E23: ic4h10 | F23: 1 | K23: =100-F23-H23-J23 | L23: =(K23*INDEX(Components!$D$2:$D$17,MATCH("ar",Components!$A$2:$A$17,0))+IF(E23="",0,F23*INDEX(Components!$D$2:$D$17,MATCH(E23,Components!$A$2:$A$17,0)))+IF(G23="",0,H23*INDEX(Components!$D$2:$D$17,MATCH(G23,Components!$A$2:$A$17,0)))+IF(I23="",0,J23*INDEX(Components!$D$2:$D$17,MATCH(I23,Components!$A$2:$A$17,0))))/100 | M23: =K23*INDEX(Components!$D$2:$D$17,MATCH("ar",Components!$A$2:$A$17,0))/(K23*INDEX(Components!$D$2:$D$17,MATCH("ar",Components!$A$2:$A$17,0))+IF(E23="",0,F23*INDEX(Components!$D$2:$D$17,MATCH(E23,Components!$A$2:$A$17,0)))+IF(G23="",0,H23*INDEX(Components!$D$2:$D$17,MATCH(G23,Components!$A$2:$A$17,0)))+IF(I23="",0,J23*INDEX(Components!$D$2:$D$17,MATCH(I23,Components!$A$2:$A$17,0)))) | N23: =MIN(15.76,IF(E23="",99,INDEX(Components!$E$2:$E$17,MATCH(E23,Components!$A$2:$A$17,0))),IF(G23="",99,INDEX(Components!$E$2:$E$17,MATCH(G23,Components!$A$2:$A$17,0))),IF(I23="",99,INDEX(Components!$E$2:$E$17,MATCH(I23,Components!$A$2:$A$17,0)))) | O23: =IF(N23<11.55,"4s, 4p and higher",IF(N23<12.91,"4p and higher",IF(N23<13.85,"3d/5s and higher",IF(N23<15.76,"high Rydberg only","none")))) | P23: =IF(E23="",0,IF(INDEX(Components!$F$2:$F$17,MATCH(E23,Components!$A$2:$A$17,0))>0,F23,0))+IF(G23="",0,IF(INDEX(Components!$F$2:$F$17,MATCH(G23,Components!$A$2:$A$17,0))>0,H23,0))+IF(I23="",0,IF(INDEX(Components!$F$2:$F$17,MATCH(I23,Components!$A$2:$A$17,0))>0,J23,0)) | Q23: H, C | R23: auto: 0.40 (10 %, 1 atm only) | S23: =IF(C23="A",'Run grid'!$B$4,IF(C23="B",'Run grid'!$B$6,'Run grid'!$B$8)) | T23: =S23*'Run grid'!$B$22 | U23: Donor alone, lowest fraction | V23: Flammable
A24: B20 | B24: Ar:iC4H10 | C24: A | D24: Ar:iC4H10 98:2 | E24: ic4h10 | F24: 2 | K24: =100-F24-H24-J24 | L24: =(K24*INDEX(Components!$D$2:$D$17,MATCH("ar",Components!$A$2:$A$17,0))+IF(E24="",0,F24*INDEX(Components!$D$2:$D$17,MATCH(E24,Components!$A$2:$A$17,0)))+IF(G24="",0,H24*INDEX(Components!$D$2:$D$17,MATCH(G24,Components!$A$2:$A$17,0)))+IF(I24="",0,J24*INDEX(Components!$D$2:$D$17,MATCH(I24,Components!$A$2:$A$17,0))))/100 | M24: =K24*INDEX(Components!$D$2:$D$17,MATCH("ar",Components!$A$2:$A$17,0))/(K24*INDEX(Components!$D$2:$D$17,MATCH("ar",Components!$A$2:$A$17,0))+IF(E24="",0,F24*INDEX(Components!$D$2:$D$17,MATCH(E24,Components!$A$2:$A$17,0)))+IF(G24="",0,H24*INDEX(Components!$D$2:$D$17,MATCH(G24,Components!$A$2:$A$17,0)))+IF(I24="",0,J24*INDEX(Components!$D$2:$D$17,MATCH(I24,Components!$A$2:$A$17,0)))) | N24: =MIN(15.76,IF(E24="",99,INDEX(Components!$E$2:$E$17,MATCH(E24,Components!$A$2:$A$17,0))),IF(G24="",99,INDEX(Components!$E$2:$E$17,MATCH(G24,Components!$A$2:$A$17,0))),IF(I24="",99,INDEX(Components!$E$2:$E$17,MATCH(I24,Components!$A$2:$A$17,0)))) | O24: =IF(N24<11.55,"4s, 4p and higher",IF(N24<12.91,"4p and higher",IF(N24<13.85,"3d/5s and higher",IF(N24<15.76,"high Rydberg only","none")))) | P24: =IF(E24="",0,IF(INDEX(Components!$F$2:$F$17,MATCH(E24,Components!$A$2:$A$17,0))>0,F24,0))+IF(G24="",0,IF(INDEX(Components!$F$2:$F$17,MATCH(G24,Components!$A$2:$A$17,0))>0,H24,0))+IF(I24="",0,IF(INDEX(Components!$F$2:$F$17,MATCH(I24,Components!$A$2:$A$17,0))>0,J24,0)) | Q24: H, C | R24: auto: 0.40 (10 %, 1 atm only) | S24: =IF(C24="A",'Run grid'!$B$4,IF(C24="B",'Run grid'!$B$6,'Run grid'!$B$8)) | T24: =S24*'Run grid'!$B$22 | U24: Donor alone; same isobutane as T2K gas | V24: Flammable
A25: B21 | B25: Ar:iC4H10 | C25: B | D25: Ar:iC4H10 97:3 | E25: ic4h10 | F25: 3 | K25: =100-F25-H25-J25 | L25: =(K25*INDEX(Components!$D$2:$D$17,MATCH("ar",Components!$A$2:$A$17,0))+IF(E25="",0,F25*INDEX(Components!$D$2:$D$17,MATCH(E25,Components!$A$2:$A$17,0)))+IF(G25="",0,H25*INDEX(Components!$D$2:$D$17,MATCH(G25,Components!$A$2:$A$17,0)))+IF(I25="",0,J25*INDEX(Components!$D$2:$D$17,MATCH(I25,Components!$A$2:$A$17,0))))/100 | M25: =K25*INDEX(Components!$D$2:$D$17,MATCH("ar",Components!$A$2:$A$17,0))/(K25*INDEX(Components!$D$2:$D$17,MATCH("ar",Components!$A$2:$A$17,0))+IF(E25="",0,F25*INDEX(Components!$D$2:$D$17,MATCH(E25,Components!$A$2:$A$17,0)))+IF(G25="",0,H25*INDEX(Components!$D$2:$D$17,MATCH(G25,Components!$A$2:$A$17,0)))+IF(I25="",0,J25*INDEX(Components!$D$2:$D$17,MATCH(I25,Components!$A$2:$A$17,0)))) | N25: =MIN(15.76,IF(E25="",99,INDEX(Components!$E$2:$E$17,MATCH(E25,Components!$A$2:$A$17,0))),IF(G25="",99,INDEX(Components!$E$2:$E$17,MATCH(G25,Components!$A$2:$A$17,0))),IF(I25="",99,INDEX(Components!$E$2:$E$17,MATCH(I25,Components!$A$2:$A$17,0)))) | O25: =IF(N25<11.55,"4s, 4p and higher",IF(N25<12.91,"4p and higher",IF(N25<13.85,"3d/5s and higher",IF(N25<15.76,"high Rydberg only","none")))) | P25: =IF(E25="",0,IF(INDEX(Components!$F$2:$F$17,MATCH(E25,Components!$A$2:$A$17,0))>0,F25,0))+IF(G25="",0,IF(INDEX(Components!$F$2:$F$17,MATCH(G25,Components!$A$2:$A$17,0))>0,H25,0))+IF(I25="",0,IF(INDEX(Components!$F$2:$F$17,MATCH(I25,Components!$A$2:$A$17,0))>0,J25,0)) | Q25: H, C | R25: auto: 0.40 (10 %, 1 atm only) | S25: =IF(C25="A",'Run grid'!$B$4,IF(C25="B",'Run grid'!$B$6,'Run grid'!$B$8)) | T25: =S25*'Run grid'!$B$22 | U25: Donor alone | V25: Flammable
A26: B22 | B26: Ar:iC4H10 | C26: C | D26: Ar:iC4H10 95:5 | E26: ic4h10 | F26: 5 | K26: =100-F26-H26-J26 | L26: =(K26*INDEX(Components!$D$2:$D$17,MATCH("ar",Components!$A$2:$A$17,0))+IF(E26="",0,F26*INDEX(Components!$D$2:$D$17,MATCH(E26,Components!$A$2:$A$17,0)))+IF(G26="",0,H26*INDEX(Components!$D$2:$D$17,MATCH(G26,Components!$A$2:$A$17,0)))+IF(I26="",0,J26*INDEX(Components!$D$2:$D$17,MATCH(I26,Components!$A$2:$A$17,0))))/100 | M26: =K26*INDEX(Components!$D$2:$D$17,MATCH("ar",Components!$A$2:$A$17,0))/(K26*INDEX(Components!$D$2:$D$17,MATCH("ar",Components!$A$2:$A$17,0))+IF(E26="",0,F26*INDEX(Components!$D$2:$D$17,MATCH(E26,Components!$A$2:$A$17,0)))+IF(G26="",0,H26*INDEX(Components!$D$2:$D$17,MATCH(G26,Components!$A$2:$A$17,0)))+IF(I26="",0,J26*INDEX(Components!$D$2:$D$17,MATCH(I26,Components!$A$2:$A$17,0)))) | N26: =MIN(15.76,IF(E26="",99,INDEX(Components!$E$2:$E$17,MATCH(E26,Components!$A$2:$A$17,0))),IF(G26="",99,INDEX(Components!$E$2:$E$17,MATCH(G26,Components!$A$2:$A$17,0))),IF(I26="",99,INDEX(Components!$E$2:$E$17,MATCH(I26,Components!$A$2:$A$17,0)))) | O26: =IF(N26<11.55,"4s, 4p and higher",IF(N26<12.91,"4p and higher",IF(N26<13.85,"3d/5s and higher",IF(N26<15.76,"high Rydberg only","none")))) | P26: =IF(E26="",0,IF(INDEX(Components!$F$2:$F$17,MATCH(E26,Components!$A$2:$A$17,0))>0,F26,0))+IF(G26="",0,IF(INDEX(Components!$F$2:$F$17,MATCH(G26,Components!$A$2:$A$17,0))>0,H26,0))+IF(I26="",0,IF(INDEX(Components!$F$2:$F$17,MATCH(I26,Components!$A$2:$A$17,0))>0,J26,0)) | Q26: H, C | R26: auto: 0.40 (10 %, 1 atm only) | S26: =IF(C26="A",'Run grid'!$B$4,IF(C26="B",'Run grid'!$B$6,'Run grid'!$B$8)) | T26: =S26*'Run grid'!$B$22 | U26: Donor alone | V26: Flammable; partial pressure 0.5 bar at 10 bar
A27: B23 | B27: Ar:DME | C27: B | D27: Ar:DME 99:1 | E27: dme | F27: 1 | K27: =100-F27-H27-J27 | L27: =(K27*INDEX(Components!$D$2:$D$17,MATCH("ar",Components!$A$2:$A$17,0))+IF(E27="",0,F27*INDEX(Components!$D$2:$D$17,MATCH(E27,Components!$A$2:$A$17,0)))+IF(G27="",0,H27*INDEX(Components!$D$2:$D$17,MATCH(G27,Components!$A$2:$A$17,0)))+IF(I27="",0,J27*INDEX(Components!$D$2:$D$17,MATCH(I27,Components!$A$2:$A$17,0))))/100 | M27: =K27*INDEX(Components!$D$2:$D$17,MATCH("ar",Components!$A$2:$A$17,0))/(K27*INDEX(Components!$D$2:$D$17,MATCH("ar",Components!$A$2:$A$17,0))+IF(E27="",0,F27*INDEX(Components!$D$2:$D$17,MATCH(E27,Components!$A$2:$A$17,0)))+IF(G27="",0,H27*INDEX(Components!$D$2:$D$17,MATCH(G27,Components!$A$2:$A$17,0)))+IF(I27="",0,J27*INDEX(Components!$D$2:$D$17,MATCH(I27,Components!$A$2:$A$17,0)))) | N27: =MIN(15.76,IF(E27="",99,INDEX(Components!$E$2:$E$17,MATCH(E27,Components!$A$2:$A$17,0))),IF(G27="",99,INDEX(Components!$E$2:$E$17,MATCH(G27,Components!$A$2:$A$17,0))),IF(I27="",99,INDEX(Components!$E$2:$E$17,MATCH(I27,Components!$A$2:$A$17,0)))) | O27: =IF(N27<11.55,"4s, 4p and higher",IF(N27<12.91,"4p and higher",IF(N27<13.85,"3d/5s and higher",IF(N27<15.76,"high Rydberg only","none")))) | P27: =IF(E27="",0,IF(INDEX(Components!$F$2:$F$17,MATCH(E27,Components!$A$2:$A$17,0))>0,F27,0))+IF(G27="",0,IF(INDEX(Components!$F$2:$F$17,MATCH(G27,Components!$A$2:$A$17,0))>0,H27,0))+IF(I27="",0,IF(INDEX(Components!$F$2:$F$17,MATCH(I27,Components!$A$2:$A$17,0))>0,J27,0)) | Q27: H, C, O | R27: none: bracket r | S27: =IF(C27="A",'Run grid'!$B$4,IF(C27="B",'Run grid'!$B$6,'Run grid'!$B$8)) | T27: =S27*'Run grid'!$B$22 | U27: Donor, no attachment | V27: Flammable; materials compatibility
A28: B24 | B28: Ar:DME | C28: B | D28: Ar:DME 98:2 | E28: dme | F28: 2 | K28: =100-F28-H28-J28 | L28: =(K28*INDEX(Components!$D$2:$D$17,MATCH("ar",Components!$A$2:$A$17,0))+IF(E28="",0,F28*INDEX(Components!$D$2:$D$17,MATCH(E28,Components!$A$2:$A$17,0)))+IF(G28="",0,H28*INDEX(Components!$D$2:$D$17,MATCH(G28,Components!$A$2:$A$17,0)))+IF(I28="",0,J28*INDEX(Components!$D$2:$D$17,MATCH(I28,Components!$A$2:$A$17,0))))/100 | M28: =K28*INDEX(Components!$D$2:$D$17,MATCH("ar",Components!$A$2:$A$17,0))/(K28*INDEX(Components!$D$2:$D$17,MATCH("ar",Components!$A$2:$A$17,0))+IF(E28="",0,F28*INDEX(Components!$D$2:$D$17,MATCH(E28,Components!$A$2:$A$17,0)))+IF(G28="",0,H28*INDEX(Components!$D$2:$D$17,MATCH(G28,Components!$A$2:$A$17,0)))+IF(I28="",0,J28*INDEX(Components!$D$2:$D$17,MATCH(I28,Components!$A$2:$A$17,0)))) | N28: =MIN(15.76,IF(E28="",99,INDEX(Components!$E$2:$E$17,MATCH(E28,Components!$A$2:$A$17,0))),IF(G28="",99,INDEX(Components!$E$2:$E$17,MATCH(G28,Components!$A$2:$A$17,0))),IF(I28="",99,INDEX(Components!$E$2:$E$17,MATCH(I28,Components!$A$2:$A$17,0)))) | O28: =IF(N28<11.55,"4s, 4p and higher",IF(N28<12.91,"4p and higher",IF(N28<13.85,"3d/5s and higher",IF(N28<15.76,"high Rydberg only","none")))) | P28: =IF(E28="",0,IF(INDEX(Components!$F$2:$F$17,MATCH(E28,Components!$A$2:$A$17,0))>0,F28,0))+IF(G28="",0,IF(INDEX(Components!$F$2:$F$17,MATCH(G28,Components!$A$2:$A$17,0))>0,H28,0))+IF(I28="",0,IF(INDEX(Components!$F$2:$F$17,MATCH(I28,Components!$A$2:$A$17,0))>0,J28,0)) | Q28: H, C, O | R28: none: bracket r | S28: =IF(C28="A",'Run grid'!$B$4,IF(C28="B",'Run grid'!$B$6,'Run grid'!$B$8)) | T28: =S28*'Run grid'!$B$22 | U28: Donor, no attachment | V28: Flammable; materials compatibility
A29: B25 | B29: Ar:DME | C29: C | D29: Ar:DME 95:5 | E29: dme | F29: 5 | K29: =100-F29-H29-J29 | L29: =(K29*INDEX(Components!$D$2:$D$17,MATCH("ar",Components!$A$2:$A$17,0))+IF(E29="",0,F29*INDEX(Components!$D$2:$D$17,MATCH(E29,Components!$A$2:$A$17,0)))+IF(G29="",0,H29*INDEX(Components!$D$2:$D$17,MATCH(G29,Components!$A$2:$A$17,0)))+IF(I29="",0,J29*INDEX(Components!$D$2:$D$17,MATCH(I29,Components!$A$2:$A$17,0))))/100 | M29: =K29*INDEX(Components!$D$2:$D$17,MATCH("ar",Components!$A$2:$A$17,0))/(K29*INDEX(Components!$D$2:$D$17,MATCH("ar",Components!$A$2:$A$17,0))+IF(E29="",0,F29*INDEX(Components!$D$2:$D$17,MATCH(E29,Components!$A$2:$A$17,0)))+IF(G29="",0,H29*INDEX(Components!$D$2:$D$17,MATCH(G29,Components!$A$2:$A$17,0)))+IF(I29="",0,J29*INDEX(Components!$D$2:$D$17,MATCH(I29,Components!$A$2:$A$17,0)))) | N29: =MIN(15.76,IF(E29="",99,INDEX(Components!$E$2:$E$17,MATCH(E29,Components!$A$2:$A$17,0))),IF(G29="",99,INDEX(Components!$E$2:$E$17,MATCH(G29,Components!$A$2:$A$17,0))),IF(I29="",99,INDEX(Components!$E$2:$E$17,MATCH(I29,Components!$A$2:$A$17,0)))) | O29: =IF(N29<11.55,"4s, 4p and higher",IF(N29<12.91,"4p and higher",IF(N29<13.85,"3d/5s and higher",IF(N29<15.76,"high Rydberg only","none")))) | P29: =IF(E29="",0,IF(INDEX(Components!$F$2:$F$17,MATCH(E29,Components!$A$2:$A$17,0))>0,F29,0))+IF(G29="",0,IF(INDEX(Components!$F$2:$F$17,MATCH(G29,Components!$A$2:$A$17,0))>0,H29,0))+IF(I29="",0,IF(INDEX(Components!$F$2:$F$17,MATCH(I29,Components!$A$2:$A$17,0))>0,J29,0)) | Q29: H, C, O | R29: none: bracket r | S29: =IF(C29="A",'Run grid'!$B$4,IF(C29="B",'Run grid'!$B$6,'Run grid'!$B$8)) | T29: =S29*'Run grid'!$B$22 | U29: Donor, no attachment | V29: Flammable; materials compatibility
A30: B26 | B30: Ar:TMA | C30: B | D30: Ar:TMA 99.5:0.5 | E30: tma | F30: 0.5 | K30: =100-F30-H30-J30 | L30: =(K30*INDEX(Components!$D$2:$D$17,MATCH("ar",Components!$A$2:$A$17,0))+IF(E30="",0,F30*INDEX(Components!$D$2:$D$17,MATCH(E30,Components!$A$2:$A$17,0)))+IF(G30="",0,H30*INDEX(Components!$D$2:$D$17,MATCH(G30,Components!$A$2:$A$17,0)))+IF(I30="",0,J30*INDEX(Components!$D$2:$D$17,MATCH(I30,Components!$A$2:$A$17,0))))/100 | M30: =K30*INDEX(Components!$D$2:$D$17,MATCH("ar",Components!$A$2:$A$17,0))/(K30*INDEX(Components!$D$2:$D$17,MATCH("ar",Components!$A$2:$A$17,0))+IF(E30="",0,F30*INDEX(Components!$D$2:$D$17,MATCH(E30,Components!$A$2:$A$17,0)))+IF(G30="",0,H30*INDEX(Components!$D$2:$D$17,MATCH(G30,Components!$A$2:$A$17,0)))+IF(I30="",0,J30*INDEX(Components!$D$2:$D$17,MATCH(I30,Components!$A$2:$A$17,0)))) | N30: =MIN(15.76,IF(E30="",99,INDEX(Components!$E$2:$E$17,MATCH(E30,Components!$A$2:$A$17,0))),IF(G30="",99,INDEX(Components!$E$2:$E$17,MATCH(G30,Components!$A$2:$A$17,0))),IF(I30="",99,INDEX(Components!$E$2:$E$17,MATCH(I30,Components!$A$2:$A$17,0)))) | O30: =IF(N30<11.55,"4s, 4p and higher",IF(N30<12.91,"4p and higher",IF(N30<13.85,"3d/5s and higher",IF(N30<15.76,"high Rydberg only","none")))) | P30: =IF(E30="",0,IF(INDEX(Components!$F$2:$F$17,MATCH(E30,Components!$A$2:$A$17,0))>0,F30,0))+IF(G30="",0,IF(INDEX(Components!$F$2:$F$17,MATCH(G30,Components!$A$2:$A$17,0))>0,H30,0))+IF(I30="",0,IF(INDEX(Components!$F$2:$F$17,MATCH(I30,Components!$A$2:$A$17,0))>0,J30,0)) | Q30: H, C, N | R30: none: bracket r | S30: =IF(C30="A",'Run grid'!$B$4,IF(C30="B",'Run grid'!$B$6,'Run grid'!$B$8)) | T30: =S30*'Run grid'!$B$22 | U30: Strongest Penning donor (IP 7.9 eV) | V30: Toxic, reactive
A31: B27 | B31: Ar:TMA | C31: B | D31: Ar:TMA 99:1 | E31: tma | F31: 1 | K31: =100-F31-H31-J31 | L31: =(K31*INDEX(Components!$D$2:$D$17,MATCH("ar",Components!$A$2:$A$17,0))+IF(E31="",0,F31*INDEX(Components!$D$2:$D$17,MATCH(E31,Components!$A$2:$A$17,0)))+IF(G31="",0,H31*INDEX(Components!$D$2:$D$17,MATCH(G31,Components!$A$2:$A$17,0)))+IF(I31="",0,J31*INDEX(Components!$D$2:$D$17,MATCH(I31,Components!$A$2:$A$17,0))))/100 | M31: =K31*INDEX(Components!$D$2:$D$17,MATCH("ar",Components!$A$2:$A$17,0))/(K31*INDEX(Components!$D$2:$D$17,MATCH("ar",Components!$A$2:$A$17,0))+IF(E31="",0,F31*INDEX(Components!$D$2:$D$17,MATCH(E31,Components!$A$2:$A$17,0)))+IF(G31="",0,H31*INDEX(Components!$D$2:$D$17,MATCH(G31,Components!$A$2:$A$17,0)))+IF(I31="",0,J31*INDEX(Components!$D$2:$D$17,MATCH(I31,Components!$A$2:$A$17,0)))) | N31: =MIN(15.76,IF(E31="",99,INDEX(Components!$E$2:$E$17,MATCH(E31,Components!$A$2:$A$17,0))),IF(G31="",99,INDEX(Components!$E$2:$E$17,MATCH(G31,Components!$A$2:$A$17,0))),IF(I31="",99,INDEX(Components!$E$2:$E$17,MATCH(I31,Components!$A$2:$A$17,0)))) | O31: =IF(N31<11.55,"4s, 4p and higher",IF(N31<12.91,"4p and higher",IF(N31<13.85,"3d/5s and higher",IF(N31<15.76,"high Rydberg only","none")))) | P31: =IF(E31="",0,IF(INDEX(Components!$F$2:$F$17,MATCH(E31,Components!$A$2:$A$17,0))>0,F31,0))+IF(G31="",0,IF(INDEX(Components!$F$2:$F$17,MATCH(G31,Components!$A$2:$A$17,0))>0,H31,0))+IF(I31="",0,IF(INDEX(Components!$F$2:$F$17,MATCH(I31,Components!$A$2:$A$17,0))>0,J31,0)) | Q31: H, C, N | R31: none: bracket r | S31: =IF(C31="A",'Run grid'!$B$4,IF(C31="B",'Run grid'!$B$6,'Run grid'!$B$8)) | T31: =S31*'Run grid'!$B$22 | U31: Strongest Penning donor | V31: Toxic, reactive
A32: B28 | B32: Ar:TMA | C32: C | D32: Ar:TMA 98:2 | E32: tma | F32: 2 | K32: =100-F32-H32-J32 | L32: =(K32*INDEX(Components!$D$2:$D$17,MATCH("ar",Components!$A$2:$A$17,0))+IF(E32="",0,F32*INDEX(Components!$D$2:$D$17,MATCH(E32,Components!$A$2:$A$17,0)))+IF(G32="",0,H32*INDEX(Components!$D$2:$D$17,MATCH(G32,Components!$A$2:$A$17,0)))+IF(I32="",0,J32*INDEX(Components!$D$2:$D$17,MATCH(I32,Components!$A$2:$A$17,0))))/100 | M32: =K32*INDEX(Components!$D$2:$D$17,MATCH("ar",Components!$A$2:$A$17,0))/(K32*INDEX(Components!$D$2:$D$17,MATCH("ar",Components!$A$2:$A$17,0))+IF(E32="",0,F32*INDEX(Components!$D$2:$D$17,MATCH(E32,Components!$A$2:$A$17,0)))+IF(G32="",0,H32*INDEX(Components!$D$2:$D$17,MATCH(G32,Components!$A$2:$A$17,0)))+IF(I32="",0,J32*INDEX(Components!$D$2:$D$17,MATCH(I32,Components!$A$2:$A$17,0)))) | N32: =MIN(15.76,IF(E32="",99,INDEX(Components!$E$2:$E$17,MATCH(E32,Components!$A$2:$A$17,0))),IF(G32="",99,INDEX(Components!$E$2:$E$17,MATCH(G32,Components!$A$2:$A$17,0))),IF(I32="",99,INDEX(Components!$E$2:$E$17,MATCH(I32,Components!$A$2:$A$17,0)))) | O32: =IF(N32<11.55,"4s, 4p and higher",IF(N32<12.91,"4p and higher",IF(N32<13.85,"3d/5s and higher",IF(N32<15.76,"high Rydberg only","none")))) | P32: =IF(E32="",0,IF(INDEX(Components!$F$2:$F$17,MATCH(E32,Components!$A$2:$A$17,0))>0,F32,0))+IF(G32="",0,IF(INDEX(Components!$F$2:$F$17,MATCH(G32,Components!$A$2:$A$17,0))>0,H32,0))+IF(I32="",0,IF(INDEX(Components!$F$2:$F$17,MATCH(I32,Components!$A$2:$A$17,0))>0,J32,0)) | Q32: H, C, N | R32: none: bracket r | S32: =IF(C32="A",'Run grid'!$B$4,IF(C32="B",'Run grid'!$B$6,'Run grid'!$B$8)) | T32: =S32*'Run grid'!$B$22 | U32: Strongest Penning donor | V32: Toxic, reactive
A33: B29 | B33: Ar:C2H2 | C33: C | D33: Ar:C2H2 99:1 | E33: c2h2 | F33: 1 | K33: =100-F33-H33-J33 | L33: =(K33*INDEX(Components!$D$2:$D$17,MATCH("ar",Components!$A$2:$A$17,0))+IF(E33="",0,F33*INDEX(Components!$D$2:$D$17,MATCH(E33,Components!$A$2:$A$17,0)))+IF(G33="",0,H33*INDEX(Components!$D$2:$D$17,MATCH(G33,Components!$A$2:$A$17,0)))+IF(I33="",0,J33*INDEX(Components!$D$2:$D$17,MATCH(I33,Components!$A$2:$A$17,0))))/100 | M33: =K33*INDEX(Components!$D$2:$D$17,MATCH("ar",Components!$A$2:$A$17,0))/(K33*INDEX(Components!$D$2:$D$17,MATCH("ar",Components!$A$2:$A$17,0))+IF(E33="",0,F33*INDEX(Components!$D$2:$D$17,MATCH(E33,Components!$A$2:$A$17,0)))+IF(G33="",0,H33*INDEX(Components!$D$2:$D$17,MATCH(G33,Components!$A$2:$A$17,0)))+IF(I33="",0,J33*INDEX(Components!$D$2:$D$17,MATCH(I33,Components!$A$2:$A$17,0)))) | N33: =MIN(15.76,IF(E33="",99,INDEX(Components!$E$2:$E$17,MATCH(E33,Components!$A$2:$A$17,0))),IF(G33="",99,INDEX(Components!$E$2:$E$17,MATCH(G33,Components!$A$2:$A$17,0))),IF(I33="",99,INDEX(Components!$E$2:$E$17,MATCH(I33,Components!$A$2:$A$17,0)))) | O33: =IF(N33<11.55,"4s, 4p and higher",IF(N33<12.91,"4p and higher",IF(N33<13.85,"3d/5s and higher",IF(N33<15.76,"high Rydberg only","none")))) | P33: =IF(E33="",0,IF(INDEX(Components!$F$2:$F$17,MATCH(E33,Components!$A$2:$A$17,0))>0,F33,0))+IF(G33="",0,IF(INDEX(Components!$F$2:$F$17,MATCH(G33,Components!$A$2:$A$17,0))>0,H33,0))+IF(I33="",0,IF(INDEX(Components!$F$2:$F$17,MATCH(I33,Components!$A$2:$A$17,0))>0,J33,0)) | Q33: H, C | R33: auto: 0.72 (cylindrical counters) | S33: =IF(C33="A",'Run grid'!$B$4,IF(C33="B",'Run grid'!$B$6,'Run grid'!$B$8)) | T33: =S33*'Run grid'!$B$22 | U33: Published high r (0.72) | V33: Partial pressure 0.1 bar at 10 bar; decomposition hazard | W33: Sahin 2010 (r)
A34: B30 | B34: Ar:C2H2 | C34: C | D34: Ar:C2H2 98:2 | E34: c2h2 | F34: 2 | K34: =100-F34-H34-J34 | L34: =(K34*INDEX(Components!$D$2:$D$17,MATCH("ar",Components!$A$2:$A$17,0))+IF(E34="",0,F34*INDEX(Components!$D$2:$D$17,MATCH(E34,Components!$A$2:$A$17,0)))+IF(G34="",0,H34*INDEX(Components!$D$2:$D$17,MATCH(G34,Components!$A$2:$A$17,0)))+IF(I34="",0,J34*INDEX(Components!$D$2:$D$17,MATCH(I34,Components!$A$2:$A$17,0))))/100 | M34: =K34*INDEX(Components!$D$2:$D$17,MATCH("ar",Components!$A$2:$A$17,0))/(K34*INDEX(Components!$D$2:$D$17,MATCH("ar",Components!$A$2:$A$17,0))+IF(E34="",0,F34*INDEX(Components!$D$2:$D$17,MATCH(E34,Components!$A$2:$A$17,0)))+IF(G34="",0,H34*INDEX(Components!$D$2:$D$17,MATCH(G34,Components!$A$2:$A$17,0)))+IF(I34="",0,J34*INDEX(Components!$D$2:$D$17,MATCH(I34,Components!$A$2:$A$17,0)))) | N34: =MIN(15.76,IF(E34="",99,INDEX(Components!$E$2:$E$17,MATCH(E34,Components!$A$2:$A$17,0))),IF(G34="",99,INDEX(Components!$E$2:$E$17,MATCH(G34,Components!$A$2:$A$17,0))),IF(I34="",99,INDEX(Components!$E$2:$E$17,MATCH(I34,Components!$A$2:$A$17,0)))) | O34: =IF(N34<11.55,"4s, 4p and higher",IF(N34<12.91,"4p and higher",IF(N34<13.85,"3d/5s and higher",IF(N34<15.76,"high Rydberg only","none")))) | P34: =IF(E34="",0,IF(INDEX(Components!$F$2:$F$17,MATCH(E34,Components!$A$2:$A$17,0))>0,F34,0))+IF(G34="",0,IF(INDEX(Components!$F$2:$F$17,MATCH(G34,Components!$A$2:$A$17,0))>0,H34,0))+IF(I34="",0,IF(INDEX(Components!$F$2:$F$17,MATCH(I34,Components!$A$2:$A$17,0))>0,J34,0)) | Q34: H, C | R34: auto: 0.72 (cylindrical counters) | S34: =IF(C34="A",'Run grid'!$B$4,IF(C34="B",'Run grid'!$B$6,'Run grid'!$B$8)) | T34: =S34*'Run grid'!$B$22 | U34: Published high r (0.72) | V34: Partial pressure 0.2 bar at 10 bar; decomposition hazard
A35: B31 | B35: Ar:N2 | C35: C | D35: Ar:N2 95:5 | E35: n2 | F35: 5 | K35: =100-F35-H35-J35 | L35: =(K35*INDEX(Components!$D$2:$D$17,MATCH("ar",Components!$A$2:$A$17,0))+IF(E35="",0,F35*INDEX(Components!$D$2:$D$17,MATCH(E35,Components!$A$2:$A$17,0)))+IF(G35="",0,H35*INDEX(Components!$D$2:$D$17,MATCH(G35,Components!$A$2:$A$17,0)))+IF(I35="",0,J35*INDEX(Components!$D$2:$D$17,MATCH(I35,Components!$A$2:$A$17,0))))/100 | M35: =K35*INDEX(Components!$D$2:$D$17,MATCH("ar",Components!$A$2:$A$17,0))/(K35*INDEX(Components!$D$2:$D$17,MATCH("ar",Components!$A$2:$A$17,0))+IF(E35="",0,F35*INDEX(Components!$D$2:$D$17,MATCH(E35,Components!$A$2:$A$17,0)))+IF(G35="",0,H35*INDEX(Components!$D$2:$D$17,MATCH(G35,Components!$A$2:$A$17,0)))+IF(I35="",0,J35*INDEX(Components!$D$2:$D$17,MATCH(I35,Components!$A$2:$A$17,0)))) | N35: =MIN(15.76,IF(E35="",99,INDEX(Components!$E$2:$E$17,MATCH(E35,Components!$A$2:$A$17,0))),IF(G35="",99,INDEX(Components!$E$2:$E$17,MATCH(G35,Components!$A$2:$A$17,0))),IF(I35="",99,INDEX(Components!$E$2:$E$17,MATCH(I35,Components!$A$2:$A$17,0)))) | O35: =IF(N35<11.55,"4s, 4p and higher",IF(N35<12.91,"4p and higher",IF(N35<13.85,"3d/5s and higher",IF(N35<15.76,"high Rydberg only","none")))) | P35: =IF(E35="",0,IF(INDEX(Components!$F$2:$F$17,MATCH(E35,Components!$A$2:$A$17,0))>0,F35,0))+IF(G35="",0,IF(INDEX(Components!$F$2:$F$17,MATCH(G35,Components!$A$2:$A$17,0))>0,H35,0))+IF(I35="",0,IF(INDEX(Components!$F$2:$F$17,MATCH(I35,Components!$A$2:$A$17,0))>0,J35,0)) | Q35: N | R35: none: bracket r | S35: =IF(C35="A",'Run grid'!$B$4,IF(C35="B",'Run grid'!$B$6,'Run grid'!$B$8)) | T35: =S35*'Run grid'!$B$22 | U35: Reference: molecular gas without Penning | V35: Poor quencher
